<?xml version="1.0"?>
<robot name="my_robot" xmlns:xacro="http://www.ros.org/wiki/xacro">

     <xacro:include filename="common_properties.xacro" />
     <xacro:include filename="mobile_base_gazebo.xacro" />
     <xacro:include filename="camera1.xacro" />
     <xacro:include filename="lider1.xacro" />
     <xacro:include filename="ulta.xacro"/>


     <xacro:property name="base_length" value="0.12" />
     <xacro:property name="base_width" value="0.8" />
    <xacro:property name="base_height" value="0.4" />
     <xacro:property name="wheel_radius" value="0.2" />
     <xacro:property name="wheel_length" value="0.10" />

     <link name="base_footprint" />

     <link name="base_link">
        <visual>
           <geometry>
                 <mesh filename="$(find my_robot_description)/meshes/body1.dae"/>
                 <!-- <mesh filename="package://my_robot_description/meshes/body1.dae"/> -->
           </geometry>
             <origin xyz="0 0 -0.1" rpy="0 0 3.14159" />
         </visual>
            <collision>
             <geometry>
                     <mesh filename="package://my_robot_description/meshes/body1.dae"/>
               <!-- <mesh filename="$(find my_robot_description)/meshes/body1.dae"/> -->
             </geometry>
                 <origin xyz="0 0 -0.1" rpy="0 0 3.14159" />
         </collision>
       
           <xacro:body_inertia m="5.0"  l="0.9" w="0.5" h="0.8" 
                                    xyz="0 0 0" rpy="0 0 0" />
 
     </link>
 
     <link name="right_wheel_link">
         <visual>
             <geometry>
                 <!-- <mesh filename="package://my_robot_description/meshes/wheel1.dae"/> -->
                 <cylinder radius="${wheel_radius}" length="0.10" />
             </geometry>
                 <origin xyz="0 0 0" rpy="1.57 0 0" />
             <material name="black" />
         </visual>
           <collision>
                 <geometry>
                     <cylinder radius="${wheel_radius}" length="${wheel_length}" />
                 </geometry>
                 <origin xyz="0 0 0" rpy="1.57 0 0" />
             </collision>
 
           <xacro:cylinder_inertia m="1.0" r="${wheel_radius}" h="${wheel_length}" 
                                    xyz="0 0 0" rpy="1.57 0 0" />
     </link>
 
     <link name="left_wheel_link">
         <visual>
             <geometry>
                 <cylinder radius="${wheel_radius}" length="0.10" />
             </geometry>
             <origin xyz="0 0 0" rpy="1.57 0 0" />
             <material name="black" />
         </visual>
             <collision>
                 <geometry>
                     <cylinder radius="${wheel_radius}" length="${wheel_length}" />
                 </geometry>
                 <origin xyz="0 0 0" rpy="1.57 0 0" />
             </collision>
 
         <xacro:cylinder_inertia m="1.0" r="${wheel_radius}" h="${wheel_length}" 
                                    xyz="0 0 0" rpy="1.57 0 0" />
     </link>
 
      <link name="back_right_wheel_link">
         <visual>
             <geometry>
                 <cylinder  radius="${wheel_radius}" length="0.10" />
             </geometry>
             <origin xyz="0 0 0" rpy="1.57 0 0" />
             <material name="black" />
         </visual>
             <collision>
                 <geometry>
                     <cylinder radius="${wheel_radius}" length="${wheel_length}" />
                 </geometry>
                 <origin xyz="0 0 0" rpy="1.57 0 0" />
             </collision>
 
        <xacro:cylinder_inertia m="1.0" r="${wheel_radius}" h="${wheel_length}" 
                                    xyz="0 0 0" rpy="1.57 0 0" />
     </link>
 
         <link name="back_left_wheel_link">
         <visual>
             <geometry>
                 <cylinder  radius="${wheel_radius}" length="0.10" />
             </geometry>
             <origin xyz="0 0 0" rpy="1.57 0 0" />
             <material name="black" />
         </visual>
             <collision>
                 <geometry>
                     <cylinder radius="${wheel_radius}" length="${wheel_length}" />
                 </geometry>
                 <origin xyz="0 0 0" rpy="1.57 0 0" />
             </collision>
 
           <xacro:cylinder_inertia m="1.0" r="${wheel_radius}" h="${wheel_length}" 
                                    xyz="0 0 0" rpy="1.57 0 0" />
     </link>
     <joint name="base_joint" type="fixed">
         <parent link="base_footprint" />
         <child link="base_link" />
         <origin xyz="0 0 0.1" rpy="0 0 0"/>
     </joint>
 
     <joint name="base_right_wheel_joint" type="continuous">
         <parent link="base_link" />
         <child link="right_wheel_link" />
         <origin xyz="-0.55 -0.480 0.1" rpy="0 0 0" />
         <axis xyz="0 1 0" />
     </joint>
 
     <joint name="base_left_wheel_joint" type="continuous">
         <parent link="base_link" />
         <child link="left_wheel_link" />
         <origin xyz="-0.55 0.480 0.1" rpy="0 0 0" />
         <axis xyz="0 1 0" />
 
     </joint>
 
       <joint name="base_back_right_wheel_joint" type="continuous">
         <parent link="base_link" />
         <child link="back_right_wheel_link" />
         <origin xyz="0.38 -0.480 0.1" rpy="0 0 0" />
         <axis xyz="0 1 0" />
         <!-- <axis xyz="0.0 0.0 0.1"/>
         <limit lower="-0.50" upper="0.50" effort="1000" velocity="3"/> -->
 
     </joint>
 
         <joint name="base_back_left_wheel_joint" type="continuous">
         <parent link="base_link" />
         <child link="back_left_wheel_link" />
         <origin xyz="0.38 0.480 0.1" rpy="0 0 0" />   
         <axis xyz="0 1 0" />
         <!-- <axis xyz="0.0 0.0 0.1"/>
     <limit effort="100.00" lower="-0.30" upper="0.30" velocity="100.00"/> -->
 
 
     </joint>
 
     <transmission name="trans_right_wheel_hing">
         <type>transmission_interface/SimpleTransmission</type>
         <joint name="base_back_right_wheel_joint">
           <hardwareInterface>EffortJointInterface</hardwareInterface>
         </joint>
         <actuator name="motor1">
           <hardwareInterface>EffortJointInterface</hardwareInterface>
           <mechanicalReduction>1</mechanicalReduction>
         </actuator>
       </transmission>
     
       <transmission name="trans_right_wheel_rotate">
         <type>transmission_interface/SimpleTransmission</type>
         <joint name="base_back_left_wheel_joint">
           <hardwareInterface>EffortJointInterface</hardwareInterface>
         </joint>
         <actuator name="motor_right_wheel_rotate">
           <hardwareInterface>EffortJointInterface</hardwareInterface>
           <mechanicalReduction>1</mechanicalReduction>
         </actuator>
       </transmission>
 </robot>