<?xml version="1.0"?>
<robot name="my_robot" xmlns:xacro="http://www.ros.org/wiki/xacro">

     <xacro:include filename="common_properties.xacro" />
     <!-- <xacro:include filename="ros2_control.xacro" /> -->
     <xacro:include filename="ackermann_controller.xacro" />
     <!-- <xacro:include filename="mobile_base_gazebo.xacro" /> -->
     <xacro:include filename="camera.xacro" />
     <xacro:include filename="lidar.xacro" />
     <xacro:include filename="ultrasonic.xacro"/>
 

     <xacro:property name="base_length" value="0.12" />
     <xacro:property name="base_width" value="0.8" />
    <xacro:property name="base_height" value="0.4" />
     <xacro:property name="wheel_radius" value="0.2" />
     <xacro:property name="wheel_length" value="0.10" />

    <link name="base_footprint">

        
    </link>

    
    <link name="base_link">
       <visual>
          <geometry>
                <mesh filename="$(find my_robot_description)/meshes/body1.dae"/>
                <!-- <mesh filename="package://my_robot_description/meshes/body1.dae"/> -->
          </geometry>
            <origin xyz="0 0 -0.1" rpy="0 0 3.14159" />
        </visual>
           <collision>
            <geometry>
                    <mesh filename="package://my_robot_description/meshes/body1.dae"/>
              <!-- <mesh filename="$(find my_robot_description)/meshes/body1.dae"/> -->
            </geometry>
                <origin xyz="0 0 -0.1" rpy="0 0 3.14159" />
        </collision>
      
          <xacro:body_inertia m="5.0"  l="0.9" w="0.5" h="0.8" 
                                   xyz="0 0 0" rpy="0 0 0" />

    </link>

    <link name="right_wheel_link">
        <visual>
            <geometry>
                <!-- <mesh filename="package://my_robot_description/meshes/wheel1.dae"/> -->
                <cylinder radius="${wheel_radius}" length="0.10" />
            </geometry>
                <origin xyz="0 0 0" rpy="1.57 0 0" />
            <material name="black" />
        </visual>
          <collision>
                <geometry>
                    <cylinder radius="${wheel_radius}" length="${wheel_length}" />
                </geometry>
                <origin xyz="0 0 0" rpy="1.57 0 0" />
            </collision>

          <xacro:cylinder_inertia m="1.0" r="${wheel_radius}" h="${wheel_length}" 
                                   xyz="0 0 0" rpy="1.57 0 0" />
    </link>

    <link name="left_wheel_link">
        <visual>
            <geometry>
                <cylinder radius="${wheel_radius}" length="0.10" />
            </geometry>
            <origin xyz="0 0 0" rpy="1.57 0 0" />
            <material name="black" />
        </visual>
            <collision>
                <geometry>
                    <cylinder radius="${wheel_radius}" length="${wheel_length}" />
                </geometry>
                <origin xyz="0 0 0" rpy="1.57 0 0" />
            </collision>

        <xacro:cylinder_inertia m="1.0" r="${wheel_radius}" h="${wheel_length}" 
                                   xyz="0 0 0" rpy="1.57 0 0" />
    </link>

     <link name="back_right_wheel_link">
        <visual>
            <geometry>
                <cylinder  radius="${wheel_radius}" length="0.10" />
            </geometry>
            <origin xyz="0 0 0" rpy="1.57 0 0" />
            <material name="black" />
        </visual>
            <collision>
                <geometry>
                    <cylinder radius="${wheel_radius}" length="${wheel_length}" />
                </geometry>
                <origin xyz="0 0 0" rpy="1.57 0 0" />
            </collision>

       <xacro:cylinder_inertia m="1.0" r="${wheel_radius}" h="${wheel_length}" 
                                   xyz="0 0 0" rpy="1.57 0 0" />
    </link>

        <link name="back_left_wheel_link">
        <visual>
            <geometry>
                <cylinder  radius="${wheel_radius}" length="0.10" />
            </geometry>
            <origin xyz="0 0 0" rpy="1.57 0 0" />
            <material name="black" />
        </visual>
            <collision>
                <geometry>
                    <cylinder radius="${wheel_radius}" length="${wheel_length}" />
                </geometry>
                <origin xyz="0 0 0" rpy="1.57 0 0" />
            </collision>

          <xacro:cylinder_inertia m="1.0" r="${wheel_radius}" h="${wheel_length}" 
                                   xyz="0 0 0" rpy="1.57 0 0" />
    </link>
    <joint name="base_joint" type="fixed">
        <parent link="base_footprint" />
        <child link="base_link" />
        <origin xyz="0 0 0.1" rpy="0 0 0"/>

    </joint>

  <link name="r_steer_1">
    <inertial>
      <origin rpy="0 0 0" xyz="0.003381 1.5929e-07 0.02162" />
      <mass value="1" />
      <inertia ixx="1.0" ixy="0.0" ixz="0.0" iyy="1.0" iyz="0.0" izz="1.0" />
    </inertial>
  </link>

  <link name="l_steer_1">
    <inertial>
      <origin rpy="0 0 0" xyz="0.003381 1.5929e-07 0.02162" />
      <mass value="1" />
      <inertia ixx="1.0" ixy="0.0" ixz="0.0" iyy="1.0" iyz="0.0" izz="1.0" />
    </inertial>
  </link>

  <joint name="r_steer" type="revolute">
    <origin xyz="0.38 -0.480 0.1" rpy="0 0 0" />
    <parent link="base_link" />
    <child link="r_steer_1" />
    <axis xyz="0.0 0.0 1.0" />
    <dynamics damping="1.0"  friction="1.0"/>
    <limit effort="100.0" lower="-0.40" upper="0.40" velocity="100" />
  </joint>

  <joint name="l_steer" type="revolute">
    <origin xyz="0.38 0.480 0.1" rpy="0 0 0" />   
    <parent link="base_link" />
    <child link="l_steer_1" />
    <axis xyz="0.0 0.0 1.0" />
    <dynamics damping="1.0"  friction="1.0"/>
    <limit effort="100.0" lower="-0.95" upper="0.95" velocity="100" />
  </joint>

    <joint name="base_right_wheel_joint" type="continuous">
        <parent link="base_link" />
        <child link="right_wheel_link" />
        <origin xyz="-0.55 -0.480 0.1" rpy="0 0 0" />
        <axis xyz="0 1 0" />
        <limit effort="10000.00" velocity="10000.00"/>
        <dynamics damping="1.0"  friction="1.0"/>
    </joint>

    <joint name="base_left_wheel_joint" type="continuous">
        <parent link="base_link" />
        <child link="left_wheel_link" />
        <origin xyz="-0.55 0.480 0.1" rpy="0 0 0" />
        <axis xyz="0 1 0" />
        <limit effort="10000.00" velocity="10000.00"/>
        <dynamics damping="1.0"  friction="1.0"/>

    </joint>
      <joint name="base_back_right_wheel_joint" type="continuous">
        <parent link="r_steer_1" />
        <child link="back_right_wheel_link" />
        <origin rpy="0 0 0" xyz="0.05 0.0 0.0" />
        <axis xyz="0 1 0" />
    
    </joint>
        <joint name="base_back_left_wheel_joint" type="continuous">
        <parent link="l_steer_1" />
        <child link="back_left_wheel_link" />
        <origin rpy="0 0 0" xyz="-0.05 0.0 0.0" />
        <axis xyz="0 1 0" />
    </joint>
</robot>
