<?xml version="1.0"?>
<sdf version='1.7'>
  <world name='default'>
    <light name='sun' type='directional'>
      <cast_shadows>1</cast_shadows>
      <pose>0 0 10 0 -0 0</pose>
      <diffuse>0.8 0.8 0.8 1</diffuse>
      <specular>0.2 0.2 0.2 1</specular>
      <attenuation>
        <range>1000</range>
        <constant>0.9</constant>
        <linear>0.01</linear>
        <quadratic>0.001</quadratic>
      </attenuation>
      <direction>-0.5 0.1 -0.9</direction>
      <spot>
        <inner_angle>0</inner_angle>
        <outer_angle>0</outer_angle>
        <falloff>0</falloff>
      </spot>
    </light>
    <model name='ground_plane'>
      <static>1</static>
      <link name='link'>
        <collision name='collision'>
          <geometry>
            <plane>
              <normal>0 0 1</normal>
              <size>100 100</size>
            </plane>
          </geometry>
          <surface>
            <friction>
              <ode>
                <mu>100</mu>
                <mu2>50</mu2>
              </ode>
              <torsional>
                <ode/>
              </torsional>
            </friction>
            <contact>
              <ode/>
            </contact>
            <bounce/>
          </surface>
          <max_contacts>10</max_contacts>
        </collision>
        <visual name='visual'>
          <cast_shadows>0</cast_shadows>
          <geometry>
            <plane>
              <normal>0 0 1</normal>
              <size>100 100</size>
            </plane>
          </geometry>
          <material>
            <script>
              <uri>file://media/materials/scripts/gazebo.material</uri>
              <name>Gazebo/Grey</name>
            </script>
          </material>
        </visual>
        <self_collide>0</self_collide>
        <enable_wind>0</enable_wind>
        <kinematic>0</kinematic>
      </link>
    </model>
    <gravity>0 0 -9.8</gravity>
    <magnetic_field>6e-06 2.3e-05 -4.2e-05</magnetic_field>
    <atmosphere type='adiabatic'/>
    <physics type='ode'>
      <max_step_size>0.001</max_step_size>
      <real_time_factor>1</real_time_factor>
      <real_time_update_rate>1000</real_time_update_rate>
    </physics>
    <scene>
      <ambient>0.4 0.4 0.4 1</ambient>
      <background>0.7 0.7 0.7 1</background>
      <shadows>1</shadows>
    </scene>
    <audio>
      <device>default</device>
    </audio>
    <wind/>
    <spherical_coordinates>
      <surface_model>EARTH_WGS84</surface_model>
      <latitude_deg>0</latitude_deg>
      <longitude_deg>0</longitude_deg>
      <elevation>0</elevation>
      <heading_deg>0</heading_deg>
    </spherical_coordinates>
    <model name='car'>
      <link name='base_footprint'>
        <inertial>
          <pose>0.364203 0 0.054291 0 -0 0</pose>
          <mass>2.80002</mass>
          <inertia>
            <ixx>0.219331</ixx>
            <ixy>2.51541e-20</ixy>
            <ixz>0.00906363</ixz>
            <iyy>0.317137</iyy>
            <iyz>-1.66183e-20</iyz>
            <izz>0.274568</izz>
          </inertia>
        </inertial>
        <collision name='base_footprint_fixed_joint_lump__back_scanner_link_collision'>
          <pose>-0.45 0 0.82 0 -0 0</pose>
          <geometry>
            <cylinder>
              <length>0.08</length>
              <radius>0.08</radius>
            </cylinder>
          </geometry>
          <surface>
            <contact>
              <ode/>
            </contact>
            <friction>
              <ode/>
              <torsional>
                <ode/>
              </torsional>
            </friction>
            <bounce/>
          </surface>
          <max_contacts>10</max_contacts>
        </collision>
        <collision name='base_footprint_fixed_joint_lump__back_camera_link_collision_1'>
          <pose>-0.6 0 0.5 3.14159 -0.058407 3.14159</pose>
          <geometry>
            <box>
              <size>0.02 0.2 0.12</size>
            </box>
          </geometry>
          <surface>
            <contact>
              <ode/>
            </contact>
            <friction>
              <ode/>
              <torsional>
                <ode/>
              </torsional>
            </friction>
            <bounce/>
          </surface>
          <max_contacts>10</max_contacts>
        </collision>
        <collision name='base_footprint_fixed_joint_lump__front_camera_link_collision_2'>
          <pose>1.14 0 0.5 0 -0 0</pose>
          <geometry>
            <box>
              <size>0.02 0.2 0.12</size>
            </box>
          </geometry>
          <surface>
            <contact>
              <ode/>
            </contact>
            <friction>
              <ode/>
              <torsional>
                <ode/>
              </torsional>
            </friction>
            <bounce/>
          </surface>
          <max_contacts>10</max_contacts>
        </collision>
        <collision name='base_footprint_fixed_joint_lump__chassis_link_collision_3'>
          <pose>0.37145 0 0.02 0 -0 3.14159</pose>
          <geometry>
            <mesh>
              <scale>1 1 1</scale>
              <uri>model://my_robot_description/meshes/body1.dae</uri>
            </mesh>
          </geometry>
          <max_contacts>10</max_contacts>
          <surface>
            <contact>
              <ode/>
            </contact>
            <bounce/>
            <friction>
              <torsional>
                <ode/>
              </torsional>
              <ode/>
            </friction>
          </surface>
        </collision>
        <collision name='base_footprint_fixed_joint_lump__laser_scanner_link_collision_4'>
          <pose>1 0 0.9 0 -0 0</pose>
          <geometry>
            <cylinder>
              <length>0.08</length>
              <radius>0.08</radius>
            </cylinder>
          </geometry>
          <surface>
            <contact>
              <ode/>
            </contact>
            <friction>
              <ode/>
              <torsional>
                <ode/>
              </torsional>
            </friction>
            <bounce/>
          </surface>
          <max_contacts>10</max_contacts>
        </collision>
        <visual name='base_footprint_fixed_joint_lump__back_scanner_link_visual'>
          <pose>-0.45 0 0.82 0 -0 0</pose>
          <geometry>
            <cylinder>
              <length>0.08</length>
              <radius>0.08</radius>
            </cylinder>
          </geometry>
          <material>
            <script>
              <name>Gazebo/Black</name>
              <uri>file://media/materials/scripts/gazebo.material</uri>
            </script>
          </material>
        </visual>
        <visual name='base_footprint_fixed_joint_lump__back_camera_link_visual_1'>
          <pose>-0.6 0 0.5 3.14159 -0.058407 3.14159</pose>
          <geometry>
            <box>
              <size>0.02 0.2 0.12</size>
            </box>
          </geometry>
          <material>
            <script>
              <name>Gazebo/Black</name>
              <uri>file://media/materials/scripts/gazebo.material</uri>
            </script>
          </material>
        </visual>
        <visual name='base_footprint_fixed_joint_lump__front_camera_link_visual_2'>
          <pose>1.14 0 0.5 0 -0 0</pose>
          <geometry>
            <box>
              <size>0.02 0.2 0.12</size>
            </box>
          </geometry>
          <material>
            <script>
              <name>Gazebo/Black</name>
              <uri>file://media/materials/scripts/gazebo.material</uri>
            </script>
          </material>
        </visual>
        <visual name='base_footprint_fixed_joint_lump__chassis_link_visual_3'>
          <pose>0.37145 0 0.02 0 -0 3.14159</pose>
          <geometry>
            <mesh>
              <scale>1 1 1</scale>
              <uri>/home/farog/ros2_ws/install/my_robot_description/share/my_robot_description/meshes/body1.dae</uri>
            </mesh>
          </geometry>
        </visual>
        <visual name='base_footprint_fixed_joint_lump__laser_scanner_link_visual_4'>
          <pose>1 0 0.9 0 -0 0</pose>
          <geometry>
            <cylinder>
              <length>0.08</length>
              <radius>0.08</radius>
            </cylinder>
          </geometry>
          <material>
            <script>
              <name>Gazebo/Black</name>
              <uri>file://media/materials/scripts/gazebo.material</uri>
            </script>
          </material>
        </visual>
        <visual name='base_footprint_fixed_joint_lump__base_laser_link_range10_visual_5'>
          <pose>0.11 -0.52 0.53 0 0 -1.5</pose>
          <geometry>
            <sphere>
              <radius>0.05</radius>
            </sphere>
          </geometry>
          <material>
            <script>
              <name>Gazebo/Red</name>
              <uri>file://media/materials/scripts/gazebo.material</uri>
            </script>
          </material>
        </visual>
        <visual name='base_footprint_fixed_joint_lump__base_laser_link_range11_visual_6'>
          <pose>-0.3 -0.52 0.53 0 0 -1.5</pose>
          <geometry>
            <sphere>
              <radius>0.05</radius>
            </sphere>
          </geometry>
          <material>
            <script>
              <name>Gazebo/Red</name>
              <uri>file://media/materials/scripts/gazebo.material</uri>
            </script>
          </material>
        </visual>
        <visual name='base_footprint_fixed_joint_lump__base_laser_link_range12_visual_7'>
          <pose>0.95 0.52 0.53 0 0 -1.5</pose>
          <geometry>
            <sphere>
              <radius>0.05</radius>
            </sphere>
          </geometry>
          <material>
            <script>
              <name>Gazebo/Red</name>
              <uri>file://media/materials/scripts/gazebo.material</uri>
            </script>
          </material>
        </visual>
        <visual name='base_footprint_fixed_joint_lump__base_laser_link_range13_visual_8'>
          <pose>0.47 0.52 0.53 0 0 -1.5</pose>
          <geometry>
            <sphere>
              <radius>0.05</radius>
            </sphere>
          </geometry>
          <material>
            <script>
              <name>Gazebo/Red</name>
              <uri>file://media/materials/scripts/gazebo.material</uri>
            </script>
          </material>
        </visual>
        <visual name='base_footprint_fixed_joint_lump__base_laser_link_range14_visual_9'>
          <pose>0.11 0.52 0.53 0 0 -1.5</pose>
          <geometry>
            <sphere>
              <radius>0.05</radius>
            </sphere>
          </geometry>
          <material>
            <script>
              <name>Gazebo/Red</name>
              <uri>file://media/materials/scripts/gazebo.material</uri>
            </script>
          </material>
        </visual>
        <visual name='base_footprint_fixed_joint_lump__base_laser_link_range15_visual_10'>
          <pose>-0.3 0.52 0.53 0 0 -1.5</pose>
          <geometry>
            <sphere>
              <radius>0.05</radius>
            </sphere>
          </geometry>
          <material>
            <script>
              <name>Gazebo/Red</name>
              <uri>file://media/materials/scripts/gazebo.material</uri>
            </script>
          </material>
        </visual>
        <visual name='base_footprint_fixed_joint_lump__base_laser_link_range1_visual_11'>
          <pose>-0.6 -0.2 0.5 3.14159 -0.058407 3.14159</pose>
          <geometry>
            <sphere>
              <radius>0.05</radius>
            </sphere>
          </geometry>
          <material>
            <script>
              <name>Gazebo/Red</name>
              <uri>file://media/materials/scripts/gazebo.material</uri>
            </script>
          </material>
        </visual>
        <visual name='base_footprint_fixed_joint_lump__base_laser_link_range2_visual_12'>
          <pose>-0.58 0.4 0.5 3.14159 -0.058407 3.14159</pose>
          <geometry>
            <sphere>
              <radius>0.05</radius>
            </sphere>
          </geometry>
          <material>
            <script>
              <name>Gazebo/Red</name>
              <uri>file://media/materials/scripts/gazebo.material</uri>
            </script>
          </material>
        </visual>
        <visual name='base_footprint_fixed_joint_lump__base_laser_link_range3_visual_13'>
          <pose>-0.58 0.2 0.5 3.14159 -0.058407 3.14159</pose>
          <geometry>
            <sphere>
              <radius>0.05</radius>
            </sphere>
          </geometry>
          <material>
            <script>
              <name>Gazebo/Red</name>
              <uri>file://media/materials/scripts/gazebo.material</uri>
            </script>
          </material>
        </visual>
        <visual name='base_footprint_fixed_joint_lump__base_laser_link_range4_visual_14'>
          <pose>1.12 -0.4 0.5 3.14159 -0.058407 3.14159</pose>
          <geometry>
            <sphere>
              <radius>0.05</radius>
            </sphere>
          </geometry>
          <material>
            <script>
              <name>Gazebo/Red</name>
              <uri>file://media/materials/scripts/gazebo.material</uri>
            </script>
          </material>
        </visual>
        <visual name='base_footprint_fixed_joint_lump__base_laser_link_range5_visual_15'>
          <pose>1.12 -0.2 0.5 3.14159 -0.058407 3.14159</pose>
          <geometry>
            <sphere>
              <radius>0.05</radius>
            </sphere>
          </geometry>
          <material>
            <script>
              <name>Gazebo/Red</name>
              <uri>file://media/materials/scripts/gazebo.material</uri>
            </script>
          </material>
        </visual>
        <visual name='base_footprint_fixed_joint_lump__base_laser_link_range6_visual_16'>
          <pose>1.12 0.4 0.5 3.14159 -0.058407 3.14159</pose>
          <geometry>
            <sphere>
              <radius>0.05</radius>
            </sphere>
          </geometry>
          <material>
            <script>
              <name>Gazebo/Red</name>
              <uri>file://media/materials/scripts/gazebo.material</uri>
            </script>
          </material>
        </visual>
        <visual name='base_footprint_fixed_joint_lump__base_laser_link_range7_visual_17'>
          <pose>1.12 0.2 0.5 3.14159 -0.058407 3.14159</pose>
          <geometry>
            <sphere>
              <radius>0.05</radius>
            </sphere>
          </geometry>
          <material>
            <script>
              <name>Gazebo/Red</name>
              <uri>file://media/materials/scripts/gazebo.material</uri>
            </script>
          </material>
        </visual>
        <visual name='base_footprint_fixed_joint_lump__base_laser_link_range8_visual_18'>
          <pose>0.95 -0.52 0.53 0 0 -1.5</pose>
          <geometry>
            <sphere>
              <radius>0.05</radius>
            </sphere>
          </geometry>
          <material>
            <script>
              <name>Gazebo/Red</name>
              <uri>file://media/materials/scripts/gazebo.material</uri>
            </script>
          </material>
        </visual>
        <visual name='base_footprint_fixed_joint_lump__base_laser_link_range9_visual_19'>
          <pose>0.47 -0.52 0.53 0 0 -1.5</pose>
          <geometry>
            <sphere>
              <radius>0.05</radius>
            </sphere>
          </geometry>
          <material>
            <script>
              <name>Gazebo/Red</name>
              <uri>file://media/materials/scripts/gazebo.material</uri>
            </script>
          </material>
        </visual>
        <visual name='base_footprint_fixed_joint_lump__base_laser_link_range_visual_20'>
          <pose>-0.58 -0.4 0.5 3.14159 -0.058407 3.14159</pose>
          <geometry>
            <sphere>
              <radius>0.05</radius>
            </sphere>
          </geometry>
          <material>
            <script>
              <name>Gazebo/Red</name>
              <uri>file://media/materials/scripts/gazebo.material</uri>
            </script>
          </material>
        </visual>
        <velocity_decay>
          <linear>7e-05</linear>
          <angular>7e-05</angular>
        </velocity_decay>
        <sensor name='camera_sensor' type='camera'>
          <visualize>0</visualize>
          <update_rate>10</update_rate>
          <plugin name='camera_controller1' filename='libgazebo_ros_camera.so'>
            <frame_name>back_camera_link</frame_name>
          </plugin>
          <pose>-0.6 0 0.5 3.14159 -0.058407 3.14159</pose>
          <camera>
            <horizontal_fov>1.047</horizontal_fov>
            <image>
              <width>320</width>
              <height>240</height>
            </image>
            <clip>
              <near>0.1</near>
              <far>100</far>
            </clip>
          </camera>
        </sensor>
        <sensor name='camera_sensor' type='camera'>
          <visualize>1</visualize>
          <update_rate>10</update_rate>
          <plugin name='camera_controller' filename='libgazebo_ros_camera.so'>
            <frame_name>front_camera_link</frame_name>
          </plugin>
          <pose>1.14 0 0.5 0 -0 0</pose>
          <camera>
            <horizontal_fov>1.047</horizontal_fov>
            <image>
              <width>320</width>
              <height>240</height>
            </image>
            <clip>
              <near>0.1</near>
              <far>100</far>
            </clip>
          </camera>
        </sensor>
        <sensor name='laser_scanner' type='ray'>
          <always_on>1</always_on>
          <update_rate>3</update_rate>
          <ray>
            <scan>
              <horizontal>
                <samples>360</samples>
                <resolution>1</resolution>
                <min_angle>-3.14159</min_angle>
                <max_angle>3.14159</max_angle>
              </horizontal>
              <vertical>
                <samples>1</samples>
                <min_angle>0</min_angle>
                <max_angle>0</max_angle>
              </vertical>
            </scan>
            <range>
              <min>0.3</min>
              <max>25</max>
              <resolution>0.1</resolution>
            </range>
          </ray>
          <plugin name='scan' filename='libgazebo_ros_ray_sensor.so'>
            <ros>
              <remapping>~/out:=scan</remapping>
            </ros>
            <output_type>sensor_msgs/LaserScan</output_type>
            <frame_name>laser_scanner_link</frame_name>
          </plugin>
          <pose>1 0 0.9 0 -0 0</pose>
        </sensor>
        <sensor name='base_laser_link_range10' type='ray'>
          <always_on>1</always_on>
          <visualize>0</visualize>
          <update_rate>50</update_rate>
          <ray>
            <scan>
              <horizontal>
                <samples>5</samples>
                <resolution>1</resolution>
                <min_angle>-0.18</min_angle>
                <max_angle>0.18</max_angle>
              </horizontal>
              <vertical>
                <samples>5</samples>
                <resolution>1</resolution>
                <min_angle>-0.01</min_angle>
                <max_angle>0.01</max_angle>
              </vertical>
            </scan>
            <range>
              <min>0.02</min>
              <max>10</max>
              <resolution>0.01</resolution>
            </range>
            <noise>
              <type>gaussian</type>
              <mean>0</mean>
              <stddev>0.01</stddev>
            </noise>
          </ray>
          <plugin name='bytes_ultrasound10' filename='libgazebo_ros_ray_sensor.so'>
            <ros>
              <namespace>distance</namespace>
              <argument>~/out:=range11</argument>
            </ros>
            <output_type>sensor_msgs/Range</output_type>
            <radiation_type>ultrasound</radiation_type>
            <frame_name>base_laser_link_range10</frame_name>
          </plugin>
          <pose>0.11 -0.52 0.53 0 0 -1.5</pose>
        </sensor>
        <sensor name='base_laser_link_range11' type='ray'>
          <always_on>1</always_on>
          <visualize>0</visualize>
          <update_rate>50</update_rate>
          <ray>
            <scan>
              <horizontal>
                <samples>5</samples>
                <resolution>1</resolution>
                <min_angle>-0.18</min_angle>
                <max_angle>0.18</max_angle>
              </horizontal>
              <vertical>
                <samples>5</samples>
                <resolution>1</resolution>
                <min_angle>-0.01</min_angle>
                <max_angle>0.01</max_angle>
              </vertical>
            </scan>
            <range>
              <min>0.02</min>
              <max>10</max>
              <resolution>0.01</resolution>
            </range>
            <noise>
              <type>gaussian</type>
              <mean>0</mean>
              <stddev>0.01</stddev>
            </noise>
          </ray>
          <plugin name='bytes_ultrasound11' filename='libgazebo_ros_ray_sensor.so'>
            <ros>
              <namespace>distance</namespace>
              <argument>~/out:=range12</argument>
            </ros>
            <output_type>sensor_msgs/Range</output_type>
            <radiation_type>ultrasound</radiation_type>
            <frame_name>base_laser_link_range11</frame_name>
          </plugin>
          <pose>-0.3 -0.52 0.53 0 0 -1.5</pose>
        </sensor>
        <sensor name='base_laser_link_range12' type='ray'>
          <always_on>1</always_on>
          <visualize>0</visualize>
          <update_rate>50</update_rate>
          <ray>
            <scan>
              <horizontal>
                <samples>5</samples>
                <resolution>1</resolution>
                <min_angle>-0.18</min_angle>
                <max_angle>0.18</max_angle>
              </horizontal>
              <vertical>
                <samples>5</samples>
                <resolution>1</resolution>
                <min_angle>-0.01</min_angle>
                <max_angle>0.01</max_angle>
              </vertical>
            </scan>
            <range>
              <min>0.02</min>
              <max>10</max>
              <resolution>0.01</resolution>
            </range>
            <noise>
              <type>gaussian</type>
              <mean>0</mean>
              <stddev>0.01</stddev>
            </noise>
          </ray>
          <plugin name='bytes_ultrasound12' filename='libgazebo_ros_ray_sensor.so'>
            <ros>
              <namespace>distance</namespace>
              <argument>~/out:=range13</argument>
            </ros>
            <output_type>sensor_msgs/Range</output_type>
            <radiation_type>ultrasound</radiation_type>
            <frame_name>base_laser_link_range12</frame_name>
          </plugin>
          <pose>0.95 0.52 0.53 0 0 -1.5</pose>
        </sensor>
        <sensor name='base_laser_link_range13' type='ray'>
          <always_on>1</always_on>
          <visualize>0</visualize>
          <update_rate>50</update_rate>
          <ray>
            <scan>
              <horizontal>
                <samples>5</samples>
                <resolution>1</resolution>
                <min_angle>-0.18</min_angle>
                <max_angle>0.18</max_angle>
              </horizontal>
              <vertical>
                <samples>5</samples>
                <resolution>1</resolution>
                <min_angle>-0.01</min_angle>
                <max_angle>0.01</max_angle>
              </vertical>
            </scan>
            <range>
              <min>0.02</min>
              <max>10</max>
              <resolution>0.01</resolution>
            </range>
            <noise>
              <type>gaussian</type>
              <mean>0</mean>
              <stddev>0.01</stddev>
            </noise>
          </ray>
          <plugin name='bytes_ultrasound13' filename='libgazebo_ros_ray_sensor.so'>
            <ros>
              <namespace>distance</namespace>
              <argument>~/out:=range14</argument>
            </ros>
            <output_type>sensor_msgs/Range</output_type>
            <radiation_type>ultrasound</radiation_type>
            <frame_name>base_laser_link_range13</frame_name>
          </plugin>
          <pose>0.47 0.52 0.53 0 0 -1.5</pose>
        </sensor>
        <sensor name='base_laser_link_range14' type='ray'>
          <always_on>1</always_on>
          <visualize>0</visualize>
          <update_rate>50</update_rate>
          <ray>
            <scan>
              <horizontal>
                <samples>5</samples>
                <resolution>1</resolution>
                <min_angle>-0.18</min_angle>
                <max_angle>0.18</max_angle>
              </horizontal>
              <vertical>
                <samples>5</samples>
                <resolution>1</resolution>
                <min_angle>-0.01</min_angle>
                <max_angle>0.01</max_angle>
              </vertical>
            </scan>
            <range>
              <min>0.02</min>
              <max>10</max>
              <resolution>0.01</resolution>
            </range>
            <noise>
              <type>gaussian</type>
              <mean>0</mean>
              <stddev>0.01</stddev>
            </noise>
          </ray>
          <plugin name='bytes_ultrasound14' filename='libgazebo_ros_ray_sensor.so'>
            <ros>
              <namespace>distance</namespace>
              <argument>~/out:=range15</argument>
            </ros>
            <output_type>sensor_msgs/Range</output_type>
            <radiation_type>ultrasound</radiation_type>
            <frame_name>base_laser_link_range14</frame_name>
          </plugin>
          <pose>0.11 0.52 0.53 0 0 -1.5</pose>
        </sensor>
        <sensor name='base_laser_link_range15' type='ray'>
          <always_on>1</always_on>
          <visualize>0</visualize>
          <update_rate>50</update_rate>
          <ray>
            <scan>
              <horizontal>
                <samples>5</samples>
                <resolution>1</resolution>
                <min_angle>-0.18</min_angle>
                <max_angle>0.18</max_angle>
              </horizontal>
              <vertical>
                <samples>5</samples>
                <resolution>1</resolution>
                <min_angle>-0.01</min_angle>
                <max_angle>0.01</max_angle>
              </vertical>
            </scan>
            <range>
              <min>0.02</min>
              <max>10</max>
              <resolution>0.01</resolution>
            </range>
            <noise>
              <type>gaussian</type>
              <mean>0</mean>
              <stddev>0.01</stddev>
            </noise>
          </ray>
          <plugin name='bytes_ultrasound15' filename='libgazebo_ros_ray_sensor.so'>
            <ros>
              <namespace>distance</namespace>
              <argument>--ros-args --remap ~/out:=range15</argument>
            </ros>
            <output_type>sensor_msgs/Range</output_type>
            <radiation_type>ultrasound</radiation_type>
            <frame_name>base_laser_link_range15</frame_name>
          </plugin>
          <pose>-0.3 0.52 0.53 0 0 -1.5</pose>
        </sensor>
        <sensor name='base_laser_link_range1' type='ray'>
          <always_on>1</always_on>
          <visualize>0</visualize>
          <update_rate>50</update_rate>
          <ray>
            <scan>
              <horizontal>
                <samples>5</samples>
                <resolution>1</resolution>
                <min_angle>-0.18</min_angle>
                <max_angle>0.18</max_angle>
              </horizontal>
              <vertical>
                <samples>5</samples>
                <resolution>1</resolution>
                <min_angle>-0.01</min_angle>
                <max_angle>0.01</max_angle>
              </vertical>
            </scan>
            <range>
              <min>0.02</min>
              <max>8</max>
              <resolution>0.01</resolution>
            </range>
            <noise>
              <type>gaussian</type>
              <mean>0</mean>
              <stddev>0.01</stddev>
            </noise>
          </ray>
          <plugin name='bytes_ultrasound1' filename='libgazebo_ros_ray_sensor.so'>
            <ros>
              <namespace>distance</namespace>
              <argument>~/out:=range2</argument>
            </ros>
            <output_type>sensor_msgs/Range</output_type>
            <radiation_type>ultrasound</radiation_type>
            <frame_name>base_laser_link_range1</frame_name>
          </plugin>
          <pose>-0.6 -0.2 0.5 3.14159 -0.058407 3.14159</pose>
        </sensor>
        <sensor name='base_laser_link_range2' type='ray'>
          <always_on>1</always_on>
          <visualize>0</visualize>
          <update_rate>50</update_rate>
          <ray>
            <scan>
              <horizontal>
                <samples>5</samples>
                <resolution>1</resolution>
                <min_angle>-0.18</min_angle>
                <max_angle>0.18</max_angle>
              </horizontal>
              <vertical>
                <samples>5</samples>
                <resolution>1</resolution>
                <min_angle>-0.01</min_angle>
                <max_angle>0.01</max_angle>
              </vertical>
            </scan>
            <range>
              <min>0.02</min>
              <max>8</max>
              <resolution>0.01</resolution>
            </range>
            <noise>
              <type>gaussian</type>
              <mean>0</mean>
              <stddev>0.01</stddev>
            </noise>
          </ray>
          <plugin name='bytes_ultrasound2' filename='libgazebo_ros_ray_sensor.so'>
            <ros>
              <namespace>distance</namespace>
              <argument>~/out:=range3</argument>
            </ros>
            <output_type>sensor_msgs/Range</output_type>
            <radiation_type>ultrasound</radiation_type>
            <frame_name>base_laser_link_range2</frame_name>
          </plugin>
          <pose>-0.58 0.4 0.5 3.14159 -0.058407 3.14159</pose>
        </sensor>
        <sensor name='base_laser_link_range3' type='ray'>
          <always_on>1</always_on>
          <visualize>0</visualize>
          <update_rate>50</update_rate>
          <ray>
            <scan>
              <horizontal>
                <samples>5</samples>
                <resolution>1</resolution>
                <min_angle>-0.18</min_angle>
                <max_angle>0.18</max_angle>
              </horizontal>
              <vertical>
                <samples>5</samples>
                <resolution>1</resolution>
                <min_angle>-0.01</min_angle>
                <max_angle>0.01</max_angle>
              </vertical>
            </scan>
            <range>
              <min>0.02</min>
              <max>8</max>
              <resolution>0.01</resolution>
            </range>
            <noise>
              <type>gaussian</type>
              <mean>0</mean>
              <stddev>0.01</stddev>
            </noise>
          </ray>
          <plugin name='bytes_ultrasound3' filename='libgazebo_ros_ray_sensor.so'>
            <ros>
              <namespace>distance</namespace>
              <argument>~/out:=range4</argument>
            </ros>
            <output_type>sensor_msgs/Range</output_type>
            <radiation_type>ultrasound</radiation_type>
            <frame_name>base_laser_link_range3</frame_name>
          </plugin>
          <pose>-0.58 0.2 0.5 3.14159 -0.058407 3.14159</pose>
        </sensor>
        <sensor name='base_laser_link_range4' type='ray'>
          <always_on>1</always_on>
          <visualize>0</visualize>
          <update_rate>50</update_rate>
          <ray>
            <scan>
              <horizontal>
                <samples>5</samples>
                <resolution>1</resolution>
                <min_angle>-0.18</min_angle>
                <max_angle>0.18</max_angle>
              </horizontal>
              <vertical>
                <samples>5</samples>
                <resolution>1</resolution>
                <min_angle>-0.01</min_angle>
                <max_angle>0.01</max_angle>
              </vertical>
            </scan>
            <range>
              <min>0.02</min>
              <max>-8</max>
              <resolution>0.01</resolution>
            </range>
            <noise>
              <type>gaussian</type>
              <mean>0</mean>
              <stddev>0.01</stddev>
            </noise>
          </ray>
          <plugin name='bytes_ultrasound4' filename='libgazebo_ros_ray_sensor.so'>
            <ros>
              <namespace>distance</namespace>
              <argument>~/out:=range5</argument>
            </ros>
            <output_type>sensor_msgs/Range</output_type>
            <radiation_type>ultrasound</radiation_type>
            <frame_name>base_laser_link_range4</frame_name>
          </plugin>
          <pose>1.12 -0.4 0.5 3.14159 -0.058407 3.14159</pose>
        </sensor>
        <sensor name='base_laser_link_range5' type='ray'>
          <always_on>1</always_on>
          <visualize>0</visualize>
          <update_rate>50</update_rate>
          <ray>
            <scan>
              <horizontal>
                <samples>5</samples>
                <resolution>1</resolution>
                <min_angle>-0.18</min_angle>
                <max_angle>0.18</max_angle>
              </horizontal>
              <vertical>
                <samples>5</samples>
                <resolution>1</resolution>
                <min_angle>-0.01</min_angle>
                <max_angle>0.01</max_angle>
              </vertical>
            </scan>
            <range>
              <min>0.02</min>
              <max>-8</max>
              <resolution>0.01</resolution>
            </range>
            <noise>
              <type>gaussian</type>
              <mean>0</mean>
              <stddev>0.01</stddev>
            </noise>
          </ray>
          <plugin name='bytes_ultrasound5' filename='libgazebo_ros_ray_sensor.so'>
            <ros>
              <namespace>distance</namespace>
              <argument>~/out:=range6</argument>
            </ros>
            <output_type>sensor_msgs/Range</output_type>
            <radiation_type>ultrasound</radiation_type>
            <frame_name>base_laser_link_range5</frame_name>
          </plugin>
          <pose>1.12 -0.2 0.5 3.14159 -0.058407 3.14159</pose>
        </sensor>
        <sensor name='base_laser_link_range6' type='ray'>
          <always_on>1</always_on>
          <visualize>0</visualize>
          <update_rate>50</update_rate>
          <ray>
            <scan>
              <horizontal>
                <samples>5</samples>
                <resolution>1</resolution>
                <min_angle>-0.18</min_angle>
                <max_angle>0.18</max_angle>
              </horizontal>
              <vertical>
                <samples>5</samples>
                <resolution>1</resolution>
                <min_angle>-0.01</min_angle>
                <max_angle>0.01</max_angle>
              </vertical>
            </scan>
            <range>
              <min>0.02</min>
              <max>-8</max>
              <resolution>0.01</resolution>
            </range>
            <noise>
              <type>gaussian</type>
              <mean>0</mean>
              <stddev>0.01</stddev>
            </noise>
          </ray>
          <plugin name='bytes_ultrasound6' filename='libgazebo_ros_ray_sensor.so'>
            <ros>
              <namespace>distance</namespace>
              <argument>~/out:=range7</argument>
            </ros>
            <output_type>sensor_msgs/Range</output_type>
            <radiation_type>ultrasound</radiation_type>
            <frame_name>base_laser_link_range6</frame_name>
          </plugin>
          <pose>1.12 0.4 0.5 3.14159 -0.058407 3.14159</pose>
        </sensor>
        <sensor name='base_laser_link_range7' type='ray'>
          <always_on>1</always_on>
          <visualize>0</visualize>
          <update_rate>50</update_rate>
          <ray>
            <scan>
              <horizontal>
                <samples>5</samples>
                <resolution>1</resolution>
                <min_angle>-0.18</min_angle>
                <max_angle>0.18</max_angle>
              </horizontal>
              <vertical>
                <samples>5</samples>
                <resolution>1</resolution>
                <min_angle>-0.01</min_angle>
                <max_angle>0.01</max_angle>
              </vertical>
            </scan>
            <range>
              <min>0.02</min>
              <max>-8</max>
              <resolution>0.01</resolution>
            </range>
            <noise>
              <type>gaussian</type>
              <mean>0</mean>
              <stddev>0.01</stddev>
            </noise>
          </ray>
          <plugin name='bytes_ultrasound7' filename='libgazebo_ros_ray_sensor.so'>
            <ros>
              <namespace>distance</namespace>
              <argument>~/out:=range8</argument>
            </ros>
            <output_type>sensor_msgs/Range</output_type>
            <radiation_type>ultrasound</radiation_type>
            <frame_name>base_laser_link_range7</frame_name>
          </plugin>
          <pose>1.12 0.2 0.5 3.14159 -0.058407 3.14159</pose>
        </sensor>
        <sensor name='base_laser_link_range8' type='ray'>
          <always_on>1</always_on>
          <visualize>0</visualize>
          <update_rate>50</update_rate>
          <ray>
            <scan>
              <horizontal>
                <samples>5</samples>
                <resolution>1</resolution>
                <min_angle>-0.18</min_angle>
                <max_angle>0.18</max_angle>
              </horizontal>
              <vertical>
                <samples>5</samples>
                <resolution>1</resolution>
                <min_angle>-0.01</min_angle>
                <max_angle>0.01</max_angle>
              </vertical>
            </scan>
            <range>
              <min>0.02</min>
              <max>10</max>
              <resolution>0.01</resolution>
            </range>
            <noise>
              <type>gaussian</type>
              <mean>0</mean>
              <stddev>0.01</stddev>
            </noise>
          </ray>
          <plugin name='bytes_ultrasound8' filename='libgazebo_ros_ray_sensor.so'>
            <ros>
              <namespace>distance</namespace>
              <argument>~/out:=range9</argument>
            </ros>
            <output_type>sensor_msgs/Range</output_type>
            <radiation_type>ultrasound</radiation_type>
            <frame_name>base_laser_link_range8</frame_name>
          </plugin>
          <pose>0.95 -0.52 0.53 0 0 -1.5</pose>
        </sensor>
        <sensor name='base_laser_link_range9' type='ray'>
          <always_on>1</always_on>
          <visualize>0</visualize>
          <update_rate>50</update_rate>
          <ray>
            <scan>
              <horizontal>
                <samples>5</samples>
                <resolution>1</resolution>
                <min_angle>-0.18</min_angle>
                <max_angle>0.18</max_angle>
              </horizontal>
              <vertical>
                <samples>5</samples>
                <resolution>1</resolution>
                <min_angle>-0.01</min_angle>
                <max_angle>0.01</max_angle>
              </vertical>
            </scan>
            <range>
              <min>0.02</min>
              <max>10</max>
              <resolution>0.01</resolution>
            </range>
            <noise>
              <type>gaussian</type>
              <mean>0</mean>
              <stddev>0.01</stddev>
            </noise>
          </ray>
          <plugin name='bytes_ultrasound9' filename='libgazebo_ros_ray_sensor.so'>
            <ros>
              <namespace>distance</namespace>
              <argument>~/out:=range10</argument>
            </ros>
            <output_type>sensor_msgs/Range</output_type>
            <radiation_type>ultrasound</radiation_type>
            <frame_name>base_laser_link_range9</frame_name>
          </plugin>
          <pose>0.47 -0.52 0.53 0 0 -1.5</pose>
        </sensor>
        <sensor name='base_laser_link_range' type='ray'>
          <always_on>1</always_on>
          <visualize>0</visualize>
          <update_rate>50</update_rate>
          <ray>
            <scan>
              <horizontal>
                <samples>5</samples>
                <resolution>1</resolution>
                <min_angle>-0.18</min_angle>
                <max_angle>0.18</max_angle>
              </horizontal>
              <vertical>
                <samples>5</samples>
                <resolution>1</resolution>
                <min_angle>-0.01</min_angle>
                <max_angle>0.01</max_angle>
              </vertical>
            </scan>
            <range>
              <min>0.02</min>
              <max>8</max>
              <resolution>0.01</resolution>
            </range>
            <noise>
              <type>gaussian</type>
              <mean>0</mean>
              <stddev>0.01</stddev>
            </noise>
          </ray>
          <plugin name='bytes_ultrasound' filename='libgazebo_ros_ray_sensor.so'>
            <ros>
              <namespace>distance</namespace>
              <argument>~/out:=range1</argument>
            </ros>
            <output_type>sensor_msgs/Range</output_type>
            <radiation_type>ultrasound</radiation_type>
            <frame_name>base_laser_link_range</frame_name>
          </plugin>
          <pose>-0.58 -0.4 0.5 3.14159 -0.058407 3.14159</pose>
        </sensor>
        <self_collide>0</self_collide>
        <enable_wind>0</enable_wind>
        <kinematic>0</kinematic>
      </link>
      <joint name='back_left_shock_joint' type='prismatic'>
        <pose relative_to='base_footprint'>-0.19 0.45 0.135 0 -0 0</pose>
        <parent>base_footprint</parent>
        <child>back_left_wheel_shock</child>
        <axis>
          <xyz>0 0 1</xyz>
          <limit>
            <lower>0</lower>
            <upper>0.27</upper>
            <effort>100</effort>
            <velocity>100</velocity>
          </limit>
          <dynamics>
            <spring_reference>0</spring_reference>
            <spring_stiffness>0</spring_stiffness>
          </dynamics>
        </axis>
      </joint>
      <link name='back_left_wheel_shock'>
        <pose relative_to='back_left_shock_joint'>0 0 0 0 -0 0</pose>
        <inertial>
          <pose>0 0 0 0 -0 0</pose>
          <mass>0.01</mass>
          <inertia>
            <ixx>0.015</ixx>
            <ixy>0</ixy>
            <ixz>0</ixz>
            <iyy>0.0375</iyy>
            <iyz>0</iyz>
            <izz>0.0375</izz>
          </inertia>
        </inertial>
        <collision name='back_left_wheel_shock_collision'>
          <pose>0 0 0.1 0 -0 0</pose>
          <geometry>
            <cylinder>
              <length>0.05</length>
              <radius>0.01</radius>
            </cylinder>
          </geometry>
          <max_contacts>10</max_contacts>
          <surface>
            <contact>
              <ode/>
            </contact>
            <bounce/>
            <friction>
              <torsional>
                <ode/>
              </torsional>
              <ode/>
            </friction>
          </surface>
        </collision>
        <visual name='back_left_wheel_shock_visual'>
          <pose>0 0 0.1 0 -0 0</pose>
          <geometry>
            <cylinder>
              <length>0.05</length>
              <radius>0.01</radius>
            </cylinder>
          </geometry>
        </visual>
        <self_collide>0</self_collide>
        <enable_wind>0</enable_wind>
        <kinematic>0</kinematic>
      </link>
      <joint name='back_left_wheel_joint' type='revolute'>
        <pose relative_to='back_left_wheel_shock'>0 0 0 -1.5708 0 0</pose>
        <parent>back_left_wheel_shock</parent>
        <child>back_left_wheel</child>
        <axis>
          <xyz>0 0 1</xyz>
          <limit>
            <effort>10000</effort>
            <velocity>500</velocity>
            <lower>-1e+16</lower>
            <upper>1e+16</upper>
          </limit>
          <dynamics>
            <spring_reference>0</spring_reference>
            <spring_stiffness>0</spring_stiffness>
          </dynamics>
        </axis>
      </joint>
      <link name='back_left_wheel'>
        <pose relative_to='back_left_wheel_joint'>0 0 0 0 -0 0</pose>
        <inertial>
          <pose>0 0 0 0 -0 0</pose>
          <mass>0.1</mass>
          <inertia>
            <ixx>0.000871275</ixx>
            <ixy>0</ixy>
            <ixz>0</ixz>
            <iyy>0.000871275</iyy>
            <iyz>0</iyz>
            <izz>0.0014112</izz>
          </inertia>
        </inertial>
        <collision name='back_left_wheel_collision'>
          <pose>0 0 0 0 -0 0</pose>
          <geometry>
            <cylinder>
              <length>0.141</length>
              <radius>0.168</radius>
            </cylinder>
          </geometry>
          <surface>
            <contact>
              <ode/>
            </contact>
            <friction>
              <ode>
                <mu>0.08</mu>
              </ode>
              <torsional>
                <ode/>
              </torsional>
            </friction>
            <bounce/>
          </surface>
          <max_contacts>10</max_contacts>
        </collision>
        <visual name='back_left_wheel_visual'>
          <pose>0 0 0 0 -0 0</pose>
          <geometry>
            <cylinder>
              <length>0.141</length>
              <radius>0.168</radius>
            </cylinder>
          </geometry>
          <material>
            <script>
              <name>Gazebo/Black</name>
              <uri>file://media/materials/scripts/gazebo.material</uri>
            </script>
          </material>
        </visual>
        <self_collide>0</self_collide>
        <enable_wind>0</enable_wind>
        <kinematic>0</kinematic>
      </link>
      <joint name='back_right_shock_joint' type='prismatic'>
        <pose relative_to='base_footprint'>-0.19 -0.45 0.135 0 -0 0</pose>
        <parent>base_footprint</parent>
        <child>back_right_wheel_shock</child>
        <axis>
          <xyz>0 0 1</xyz>
          <limit>
            <lower>0</lower>
            <upper>0.27</upper>
            <effort>100</effort>
            <velocity>100</velocity>
          </limit>
          <dynamics>
            <spring_reference>0</spring_reference>
            <spring_stiffness>0</spring_stiffness>
          </dynamics>
        </axis>
      </joint>
      <link name='back_right_wheel_shock'>
        <pose relative_to='back_right_shock_joint'>0 0 0 0 -0 0</pose>
        <inertial>
          <pose>0 0 0 0 -0 0</pose>
          <mass>0.01</mass>
          <inertia>
            <ixx>0.015</ixx>
            <ixy>0</ixy>
            <ixz>0</ixz>
            <iyy>0.0375</iyy>
            <iyz>0</iyz>
            <izz>0.0375</izz>
          </inertia>
        </inertial>
        <collision name='back_right_wheel_shock_collision'>
          <pose>0 0 0.1 0 -0 0</pose>
          <geometry>
            <cylinder>
              <length>0.05</length>
              <radius>0.01</radius>
            </cylinder>
          </geometry>
          <max_contacts>10</max_contacts>
          <surface>
            <contact>
              <ode/>
            </contact>
            <bounce/>
            <friction>
              <torsional>
                <ode/>
              </torsional>
              <ode/>
            </friction>
          </surface>
        </collision>
        <visual name='back_right_wheel_shock_visual'>
          <pose>0 0 0.1 0 -0 0</pose>
          <geometry>
            <cylinder>
              <length>0.05</length>
              <radius>0.01</radius>
            </cylinder>
          </geometry>
        </visual>
        <self_collide>0</self_collide>
        <enable_wind>0</enable_wind>
        <kinematic>0</kinematic>
      </link>
      <joint name='back_right_wheel_joint' type='revolute'>
        <pose relative_to='back_right_wheel_shock'>0 0 0 -1.5708 0 0</pose>
        <parent>back_right_wheel_shock</parent>
        <child>back_right_wheel</child>
        <axis>
          <xyz>0 0 1</xyz>
          <limit>
            <effort>10000</effort>
            <velocity>500</velocity>
            <lower>-1e+16</lower>
            <upper>1e+16</upper>
          </limit>
          <dynamics>
            <spring_reference>0</spring_reference>
            <spring_stiffness>0</spring_stiffness>
          </dynamics>
        </axis>
      </joint>
      <link name='back_right_wheel'>
        <pose relative_to='back_right_wheel_joint'>0 0 0 0 -0 0</pose>
        <inertial>
          <pose>0 0 0 0 -0 0</pose>
          <mass>0.1</mass>
          <inertia>
            <ixx>0.000871275</ixx>
            <ixy>0</ixy>
            <ixz>0</ixz>
            <iyy>0.000871275</iyy>
            <iyz>0</iyz>
            <izz>0.0014112</izz>
          </inertia>
        </inertial>
        <collision name='back_right_wheel_collision'>
          <pose>0 0 0 0 -0 0</pose>
          <geometry>
            <cylinder>
              <length>0.141</length>
              <radius>0.168</radius>
            </cylinder>
          </geometry>
          <surface>
            <contact>
              <ode/>
            </contact>
            <friction>
              <ode>
                <mu>0.08</mu>
              </ode>
              <torsional>
                <ode/>
              </torsional>
            </friction>
            <bounce/>
          </surface>
          <max_contacts>10</max_contacts>
        </collision>
        <visual name='back_right_wheel_visual'>
          <pose>0 0 0 0 -0 0</pose>
          <geometry>
            <cylinder>
              <length>0.141</length>
              <radius>0.168</radius>
            </cylinder>
          </geometry>
          <material>
            <script>
              <name>Gazebo/Black</name>
              <uri>file://media/materials/scripts/gazebo.material</uri>
            </script>
          </material>
        </visual>
        <self_collide>0</self_collide>
        <enable_wind>0</enable_wind>
        <kinematic>0</kinematic>
      </link>
      <joint name='front_left_shock_joint' type='prismatic'>
        <pose relative_to='base_footprint'>0.7429 0.45 0.135 0 -0 0</pose>
        <parent>base_footprint</parent>
        <child>front_left_wheel_shock</child>
        <axis>
          <xyz>0 0 1</xyz>
          <limit>
            <lower>0</lower>
            <upper>0.27</upper>
            <effort>100</effort>
            <velocity>100</velocity>
          </limit>
          <dynamics>
            <spring_reference>0</spring_reference>
            <spring_stiffness>0</spring_stiffness>
          </dynamics>
        </axis>
      </joint>
      <link name='front_left_wheel_shock'>
        <pose relative_to='front_left_shock_joint'>0 0 0 0 -0 0</pose>
        <inertial>
          <pose>0 0 0 0 -0 0</pose>
          <mass>0.01</mass>
          <inertia>
            <ixx>0.015</ixx>
            <ixy>0</ixy>
            <ixz>0</ixz>
            <iyy>0.0375</iyy>
            <iyz>0</iyz>
            <izz>0.0375</izz>
          </inertia>
        </inertial>
        <collision name='front_left_wheel_shock_collision'>
          <pose>0 0 0.1 0 -0 0</pose>
          <geometry>
            <cylinder>
              <length>0.05</length>
              <radius>0.01</radius>
            </cylinder>
          </geometry>
          <max_contacts>10</max_contacts>
          <surface>
            <contact>
              <ode/>
            </contact>
            <bounce/>
            <friction>
              <torsional>
                <ode/>
              </torsional>
              <ode/>
            </friction>
          </surface>
        </collision>
        <visual name='front_left_wheel_shock_visual'>
          <pose>0 0 0.1 0 -0 0</pose>
          <geometry>
            <cylinder>
              <length>0.05</length>
              <radius>0.01</radius>
            </cylinder>
          </geometry>
        </visual>
        <self_collide>0</self_collide>
        <enable_wind>0</enable_wind>
        <kinematic>0</kinematic>
      </link>
      <joint name='front_left_wheel_steer_joint' type='revolute'>
        <pose relative_to='front_left_wheel_shock'>0 0 0 0 -0 0</pose>
        <parent>front_left_wheel_shock</parent>
        <child>front_left_wheel_steer</child>
        <axis>
          <xyz>0 0 1</xyz>
          <limit>
            <lower>-1</lower>
            <upper>1</upper>
            <effort>1</effort>
            <velocity>5</velocity>
          </limit>
          <dynamics>
            <spring_reference>0</spring_reference>
            <spring_stiffness>0</spring_stiffness>
          </dynamics>
        </axis>
      </joint>
      <link name='front_left_wheel_steer'>
        <pose relative_to='front_left_wheel_steer_joint'>0 0 0 0 -0 0</pose>
        <inertial>
          <pose>0 0 0 0 -0 0</pose>
          <mass>0.1</mass>
          <inertia>
            <ixx>5.1458e-05</ixx>
            <ixy>0</ixy>
            <ixz>0</ixz>
            <iyy>5.1458e-05</iyy>
            <iyz>0</iyz>
            <izz>6.125e-05</izz>
          </inertia>
        </inertial>
        <collision name='front_left_wheel_steer_collision'>
          <pose>0 0 0 0 -0 0</pose>
          <geometry>
            <cylinder>
              <length>0.01</length>
              <radius>0.01</radius>
            </cylinder>
          </geometry>
          <max_contacts>10</max_contacts>
          <surface>
            <contact>
              <ode/>
            </contact>
            <bounce/>
            <friction>
              <torsional>
                <ode/>
              </torsional>
              <ode/>
            </friction>
          </surface>
        </collision>
        <visual name='front_left_wheel_steer_visual'>
          <pose>0 0 0 0 -0 0</pose>
          <geometry>
            <cylinder>
              <length>0.01</length>
              <radius>0.01</radius>
            </cylinder>
          </geometry>
        </visual>
        <self_collide>0</self_collide>
        <enable_wind>0</enable_wind>
        <kinematic>0</kinematic>
      </link>
      <joint name='front_left_wheel_joint' type='revolute'>
        <pose relative_to='front_left_wheel_steer'>0 0 0 -1.5708 0 0</pose>
        <parent>front_left_wheel_steer</parent>
        <child>front_left_wheel</child>
        <axis>
          <xyz>0 0 1</xyz>
          <limit>
            <lower>-1e+16</lower>
            <upper>1e+16</upper>
          </limit>
          <dynamics>
            <spring_reference>0</spring_reference>
            <spring_stiffness>0</spring_stiffness>
          </dynamics>
        </axis>
      </joint>
      <link name='front_left_wheel'>
        <pose relative_to='front_left_wheel_joint'>0 0 0 0 -0 0</pose>
        <inertial>
          <pose>0 0 0 0 -0 0</pose>
          <mass>0.1</mass>
          <inertia>
            <ixx>0.000871275</ixx>
            <ixy>0</ixy>
            <ixz>0</ixz>
            <iyy>0.000871275</iyy>
            <iyz>0</iyz>
            <izz>0.0014112</izz>
          </inertia>
        </inertial>
        <collision name='front_left_wheel_collision'>
          <pose>0 0 0 0 -0 0</pose>
          <geometry>
            <cylinder>
              <length>0.141</length>
              <radius>0.168</radius>
            </cylinder>
          </geometry>
          <surface>
            <contact>
              <ode/>
            </contact>
            <friction>
              <ode>
                <mu>0.08</mu>
              </ode>
              <torsional>
                <ode/>
              </torsional>
            </friction>
            <bounce/>
          </surface>
          <max_contacts>10</max_contacts>
        </collision>
        <visual name='front_left_wheel_visual'>
          <pose>0 0 0 0 -0 0</pose>
          <geometry>
            <cylinder>
              <length>0.141</length>
              <radius>0.168</radius>
            </cylinder>
          </geometry>
          <material>
            <script>
              <name>Gazebo/Black</name>
              <uri>file://media/materials/scripts/gazebo.material</uri>
            </script>
          </material>
        </visual>
        <self_collide>0</self_collide>
        <enable_wind>0</enable_wind>
        <kinematic>0</kinematic>
      </link>
      <joint name='front_right_shock_joint' type='prismatic'>
        <pose relative_to='base_footprint'>0.7429 -0.45 0.135 0 -0 0</pose>
        <parent>base_footprint</parent>
        <child>front_right_wheel_shock</child>
        <axis>
          <xyz>0 0 1</xyz>
          <limit>
            <lower>0</lower>
            <upper>0.27</upper>
            <effort>100</effort>
            <velocity>100</velocity>
          </limit>
          <dynamics>
            <spring_reference>0</spring_reference>
            <spring_stiffness>0</spring_stiffness>
          </dynamics>
        </axis>
      </joint>
      <link name='front_right_wheel_shock'>
        <pose relative_to='front_right_shock_joint'>0 0 0 0 -0 0</pose>
        <inertial>
          <pose>0 0 0 0 -0 0</pose>
          <mass>0.01</mass>
          <inertia>
            <ixx>0.015</ixx>
            <ixy>0</ixy>
            <ixz>0</ixz>
            <iyy>0.0375</iyy>
            <iyz>0</iyz>
            <izz>0.0375</izz>
          </inertia>
        </inertial>
        <collision name='front_right_wheel_shock_collision'>
          <pose>0 0 0.1 0 -0 0</pose>
          <geometry>
            <cylinder>
              <length>0.05</length>
              <radius>0.01</radius>
            </cylinder>
          </geometry>
          <max_contacts>10</max_contacts>
          <surface>
            <contact>
              <ode/>
            </contact>
            <bounce/>
            <friction>
              <torsional>
                <ode/>
              </torsional>
              <ode/>
            </friction>
          </surface>
        </collision>
        <visual name='front_right_wheel_shock_visual'>
          <pose>0 0 0.1 0 -0 0</pose>
          <geometry>
            <cylinder>
              <length>0.05</length>
              <radius>0.01</radius>
            </cylinder>
          </geometry>
        </visual>
        <self_collide>0</self_collide>
        <enable_wind>0</enable_wind>
        <kinematic>0</kinematic>
      </link>
      <joint name='front_right_wheel_steer_joint' type='revolute'>
        <pose relative_to='front_right_wheel_shock'>0 0 0 0 -0 0</pose>
        <parent>front_right_wheel_shock</parent>
        <child>front_right_wheel_steer</child>
        <axis>
          <xyz>0 0 1</xyz>
          <limit>
            <lower>-1</lower>
            <upper>1</upper>
            <effort>1</effort>
            <velocity>5</velocity>
          </limit>
          <dynamics>
            <spring_reference>0</spring_reference>
            <spring_stiffness>0</spring_stiffness>
          </dynamics>
        </axis>
      </joint>
      <link name='front_right_wheel_steer'>
        <pose relative_to='front_right_wheel_steer_joint'>0 0 0 0 -0 0</pose>
        <inertial>
          <pose>0 0 0 0 -0 0</pose>
          <mass>0.1</mass>
          <inertia>
            <ixx>5.1458e-05</ixx>
            <ixy>0</ixy>
            <ixz>0</ixz>
            <iyy>5.1458e-05</iyy>
            <iyz>0</iyz>
            <izz>6.125e-05</izz>
          </inertia>
        </inertial>
        <collision name='front_right_wheel_steer_collision'>
          <pose>0 0 0 0 -0 0</pose>
          <geometry>
            <cylinder>
              <length>0.01</length>
              <radius>0.01</radius>
            </cylinder>
          </geometry>
          <max_contacts>10</max_contacts>
          <surface>
            <contact>
              <ode/>
            </contact>
            <bounce/>
            <friction>
              <torsional>
                <ode/>
              </torsional>
              <ode/>
            </friction>
          </surface>
        </collision>
        <visual name='front_right_wheel_steer_visual'>
          <pose>0 0 0 0 -0 0</pose>
          <geometry>
            <cylinder>
              <length>0.01</length>
              <radius>0.01</radius>
            </cylinder>
          </geometry>
        </visual>
        <self_collide>0</self_collide>
        <enable_wind>0</enable_wind>
        <kinematic>0</kinematic>
      </link>
      <joint name='front_right_wheel_joint' type='revolute'>
        <pose relative_to='front_right_wheel_steer'>0 0 0 -1.5708 0 0</pose>
        <parent>front_right_wheel_steer</parent>
        <child>front_right_wheel</child>
        <axis>
          <xyz>0 0 1</xyz>
          <limit>
            <lower>-1e+16</lower>
            <upper>1e+16</upper>
          </limit>
          <dynamics>
            <spring_reference>0</spring_reference>
            <spring_stiffness>0</spring_stiffness>
          </dynamics>
        </axis>
      </joint>
      <link name='front_right_wheel'>
        <pose relative_to='front_right_wheel_joint'>0 0 0 0 -0 0</pose>
        <inertial>
          <pose>0 0 0 0 -0 0</pose>
          <mass>0.1</mass>
          <inertia>
            <ixx>0.000871275</ixx>
            <ixy>0</ixy>
            <ixz>0</ixz>
            <iyy>0.000871275</iyy>
            <iyz>0</iyz>
            <izz>0.0014112</izz>
          </inertia>
        </inertial>
        <collision name='front_right_wheel_collision'>
          <pose>0 0 0 0 -0 0</pose>
          <geometry>
            <cylinder>
              <length>0.141</length>
              <radius>0.168</radius>
            </cylinder>
          </geometry>
          <surface>
            <contact>
              <ode/>
            </contact>
            <friction>
              <ode>
                <mu>0.08</mu>
              </ode>
              <torsional>
                <ode/>
              </torsional>
            </friction>
            <bounce/>
          </surface>
          <max_contacts>10</max_contacts>
        </collision>
        <visual name='front_right_wheel_visual'>
          <pose>0 0 0 0 -0 0</pose>
          <geometry>
            <cylinder>
              <length>0.141</length>
              <radius>0.168</radius>
            </cylinder>
          </geometry>
          <material>
            <script>
              <name>Gazebo/Black</name>
              <uri>file://media/materials/scripts/gazebo.material</uri>
            </script>
          </material>
        </visual>
        <self_collide>0</self_collide>
        <enable_wind>0</enable_wind>
        <kinematic>0</kinematic>
      </link>
      <static>0</static>
      <plugin name='car_gazebo_plugin' filename='libcar_gazebo_plugin.so'/>
      <pose>0 0 0 0 -0 0</pose>
    </model>
    <model name='Gas Station'>
      <static>1</static>
      <link name='link'>
        <pose>0 0 0 0 -0 0</pose>
        <collision name='collision'>
          <geometry>
            <mesh>
              <uri>model://gas_station/meshes/gas_station.dae</uri>
            </mesh>
          </geometry>
          <max_contacts>10</max_contacts>
          <surface>
            <contact>
              <ode/>
            </contact>
            <bounce/>
            <friction>
              <torsional>
                <ode/>
              </torsional>
              <ode/>
            </friction>
          </surface>
        </collision>
        <visual name='visual'>
          <geometry>
            <mesh>
              <uri>model://gas_station/meshes/gas_station.dae</uri>
            </mesh>
          </geometry>
          <material>
            <script>
              <uri>model://gas_station/materials/scripts</uri>
              <uri>model://gas_station/materials/textures</uri>
              <name>GasStation/Diffuse</name>
            </script>
            <shader type='normal_map_tangent_space'>
              <normal_map>GasStation_Normal.png</normal_map>
            </shader>
          </material>
        </visual>
        <self_collide>0</self_collide>
        <enable_wind>0</enable_wind>
        <kinematic>0</kinematic>
      </link>
      <pose>-11.5953 20.4063 0 0 -0 0</pose>
    </model>
    <model name='law_office'>
      <static>1</static>
      <link name='link'>
        <collision name='collision'>
          <pose>0 0 6.96244 0 -0 0</pose>
          <geometry>
            <box>
              <size>6.84401 5.43165 13.9249</size>
            </box>
          </geometry>
          <max_contacts>10</max_contacts>
          <surface>
            <contact>
              <ode/>
            </contact>
            <bounce/>
            <friction>
              <torsional>
                <ode/>
              </torsional>
              <ode/>
            </friction>
          </surface>
        </collision>
        <visual name='visual'>
          <geometry>
            <mesh>
              <uri>model://law_office/meshes/law_office.dae</uri>
            </mesh>
          </geometry>
        </visual>
        <self_collide>0</self_collide>
        <enable_wind>0</enable_wind>
        <kinematic>0</kinematic>
      </link>
      <pose>9.03494 21.7982 0 0 -0 0</pose>
    </model>
    <model name='House 2'>
      <static>1</static>
      <link name='link'>
        <collision name='collision'>
          <geometry>
            <mesh>
              <uri>model://house_2/meshes/house_2.dae</uri>
              <scale>1.5 1.5 1.5</scale>
            </mesh>
          </geometry>
          <max_contacts>10</max_contacts>
          <surface>
            <contact>
              <ode/>
            </contact>
            <bounce/>
            <friction>
              <torsional>
                <ode/>
              </torsional>
              <ode/>
            </friction>
          </surface>
        </collision>
        <visual name='visual'>
          <geometry>
            <mesh>
              <uri>model://house_2/meshes/house_2.dae</uri>
              <scale>1.5 1.5 1.5</scale>
            </mesh>
          </geometry>
          <material>
            <script>
              <uri>model://house_2/materials/scripts</uri>
              <uri>model://house_2/materials/textures</uri>
              <uri>model://house_1/materials/textures</uri>
              <name>House_2/Diffuse</name>
            </script>
            <shader type='normal_map_tangent_space'>
              <normal_map>model://house_1/materials/textures/House_1_Normal.png</normal_map>
            </shader>
          </material>
        </visual>
        <self_collide>0</self_collide>
        <enable_wind>0</enable_wind>
        <kinematic>0</kinematic>
      </link>
      <pose>-11.6117 -16.1808 0 0 -0 0</pose>
    </model>
    <model name='Construction Cone'>
      <link name='link'>
        <collision name='collision'>
          <geometry>
            <mesh>
              <scale>10 10 10</scale>
              <uri>model://construction_cone/meshes/construction_cone.dae</uri>
            </mesh>
          </geometry>
          <max_contacts>10</max_contacts>
          <surface>
            <contact>
              <ode/>
            </contact>
            <bounce/>
            <friction>
              <torsional>
                <ode/>
              </torsional>
              <ode/>
            </friction>
          </surface>
        </collision>
        <visual name='visual'>
          <geometry>
            <mesh>
              <scale>10 10 10</scale>
              <uri>model://construction_cone/meshes/construction_cone.dae</uri>
            </mesh>
          </geometry>
        </visual>
        <self_collide>0</self_collide>
        <inertial>
          <pose>0 0 0 0 -0 0</pose>
          <inertia>
            <ixx>1</ixx>
            <ixy>0</ixy>
            <ixz>0</ixz>
            <iyy>1</iyy>
            <iyz>0</iyz>
            <izz>1</izz>
          </inertia>
          <mass>1</mass>
        </inertial>
        <enable_wind>0</enable_wind>
        <kinematic>0</kinematic>
      </link>
      <pose>4.54246 -4.39477 0 0 -0 0</pose>
    </model>
    <model name='pine_tree'>
      <static>1</static>
      <link name='link'>
        <collision name='collision'>
          <geometry>
            <mesh>
              <uri>model://pine_tree/meshes/pine_tree.dae</uri>
            </mesh>
          </geometry>
          <max_contacts>10</max_contacts>
          <surface>
            <contact>
              <ode/>
            </contact>
            <bounce/>
            <friction>
              <torsional>
                <ode/>
              </torsional>
              <ode/>
            </friction>
          </surface>
        </collision>
        <visual name='branch'>
          <geometry>
            <mesh>
              <uri>model://pine_tree/meshes/pine_tree.dae</uri>
              <submesh>
                <name>Branch</name>
              </submesh>
            </mesh>
          </geometry>
          <material>
            <script>
              <uri>model://pine_tree/materials/scripts/</uri>
              <uri>model://pine_tree/materials/textures/</uri>
              <name>PineTree/Branch</name>
            </script>
          </material>
        </visual>
        <visual name='bark'>
          <geometry>
            <mesh>
              <uri>model://pine_tree/meshes/pine_tree.dae</uri>
              <submesh>
                <name>Bark</name>
              </submesh>
            </mesh>
          </geometry>
          <material>
            <script>
              <uri>model://pine_tree/materials/scripts/</uri>
              <uri>model://pine_tree/materials/textures/</uri>
              <name>PineTree/Bark</name>
            </script>
          </material>
        </visual>
        <self_collide>0</self_collide>
        <enable_wind>0</enable_wind>
        <kinematic>0</kinematic>
      </link>
      <pose>19.4895 12.7233 0 0 -0 0</pose>
    </model>
    <model name='pine_tree_0'>
      <static>1</static>
      <link name='link'>
        <collision name='collision'>
          <geometry>
            <mesh>
              <uri>model://pine_tree/meshes/pine_tree.dae</uri>
            </mesh>
          </geometry>
          <max_contacts>10</max_contacts>
          <surface>
            <contact>
              <ode/>
            </contact>
            <bounce/>
            <friction>
              <torsional>
                <ode/>
              </torsional>
              <ode/>
            </friction>
          </surface>
        </collision>
        <visual name='branch'>
          <geometry>
            <mesh>
              <uri>model://pine_tree/meshes/pine_tree.dae</uri>
              <submesh>
                <name>Branch</name>
              </submesh>
            </mesh>
          </geometry>
          <material>
            <script>
              <uri>model://pine_tree/materials/scripts/</uri>
              <uri>model://pine_tree/materials/textures/</uri>
              <name>PineTree/Branch</name>
            </script>
          </material>
        </visual>
        <visual name='bark'>
          <geometry>
            <mesh>
              <uri>model://pine_tree/meshes/pine_tree.dae</uri>
              <submesh>
                <name>Bark</name>
              </submesh>
            </mesh>
          </geometry>
          <material>
            <script>
              <uri>model://pine_tree/materials/scripts/</uri>
              <uri>model://pine_tree/materials/textures/</uri>
              <name>PineTree/Bark</name>
            </script>
          </material>
        </visual>
        <self_collide>0</self_collide>
        <enable_wind>0</enable_wind>
        <kinematic>0</kinematic>
      </link>
      <pose>14.5466 13.5254 0 0 -0 0</pose>
    </model>
    <model name='bus'>
      <static>1</static>
      <link name='link'>
        <collision name='collision'>
          <geometry>
            <mesh>
              <scale>0.01 0.01 0.01</scale>
              <uri>model://bus/meshes/bus.obj</uri>
            </mesh>
          </geometry>
          <max_contacts>10</max_contacts>
          <surface>
            <contact>
              <ode/>
            </contact>
            <bounce/>
            <friction>
              <torsional>
                <ode/>
              </torsional>
              <ode/>
            </friction>
          </surface>
        </collision>
        <visual name='visual'>
          <geometry>
            <mesh>
              <scale>0.01 0.01 0.01</scale>
              <uri>model://bus/meshes/bus.obj</uri>
            </mesh>
          </geometry>
        </visual>
        <self_collide>0</self_collide>
        <enable_wind>0</enable_wind>
        <kinematic>0</kinematic>
      </link>
      <pose>0.3925 -15.6909 0 0 -0 0</pose>
    </model>
    <model name='Stop Sign'>
      <static>1</static>
      <link name='link'>
        <collision name='collision'>
          <geometry>
            <mesh>
              <uri>model://stop_sign/meshes/stop_sign.dae</uri>
            </mesh>
          </geometry>
          <max_contacts>10</max_contacts>
          <surface>
            <contact>
              <ode/>
            </contact>
            <bounce/>
            <friction>
              <torsional>
                <ode/>
              </torsional>
              <ode/>
            </friction>
          </surface>
        </collision>
        <visual name='visual'>
          <geometry>
            <mesh>
              <uri>model://stop_sign/meshes/stop_sign.dae</uri>
            </mesh>
          </geometry>
          <material>
            <script>
              <uri>model://stop_sign/materials/scripts</uri>
              <uri>model://stop_sign/materials/textures</uri>
              <name>StopSign/Diffuse</name>
            </script>
          </material>
        </visual>
        <self_collide>0</self_collide>
        <enable_wind>0</enable_wind>
        <kinematic>0</kinematic>
      </link>
      <pose>18.4968 -12.587 0 0 -0 0</pose>
    </model>
    <state world_name='default'>
      <sim_time>416 478000000</sim_time>
      <real_time>423 232662187</real_time>
      <wall_time>1699967559 512586296</wall_time>
      <iterations>416478</iterations>
      <model name='Construction Cone'>
        <pose>4.54246 -4.39477 -0 0 -0 0</pose>
        <scale>1 1 1</scale>
        <link name='link'>
          <pose>4.54246 -4.39477 -0 0 -0 0</pose>
          <velocity>0 0 0 0 -0 0</velocity>
          <acceleration>-0 -1e-06 8.89327 -2.32657 -0.382965 -1e-06</acceleration>
          <wrench>-0 -1e-06 8.89327 0 -0 0</wrench>
        </link>
      </model>
      <model name='Gas Station'>
        <pose>-11.5953 21.6822 0 0 -0 0</pose>
        <scale>1 1 1</scale>
        <link name='link'>
          <pose>-11.5953 21.6822 0 0 -0 0</pose>
          <velocity>0 0 0 0 -0 0</velocity>
          <acceleration>0 0 0 0 -0 0</acceleration>
          <wrench>0 0 0 0 -0 0</wrench>
        </link>
      </model>
      <model name='House 2'>
        <pose>-11.7625 -11.2835 0 0 -0 1.57163</pose>
        <scale>1 1 1</scale>
        <link name='link'>
          <pose>-11.7625 -11.2835 0 0 -0 1.57163</pose>
          <velocity>0 0 0 0 -0 0</velocity>
          <acceleration>0 0 0 0 -0 0</acceleration>
          <wrench>0 0 0 0 -0 0</wrench>
        </link>
      </model>
      <model name='Stop Sign'>
        <pose>18.4968 -12.587 0 0 0 -1.37664</pose>
        <scale>1 1 1</scale>
        <link name='link'>
          <pose>18.4968 -12.587 0 0 0 -1.37664</pose>
          <velocity>0 0 0 0 -0 0</velocity>
          <acceleration>0 0 0 0 -0 0</acceleration>
          <wrench>0 0 0 0 -0 0</wrench>
        </link>
      </model>
      <model name='bus'>
        <pose>3.41191 -16.2936 0 0 -0 1.60031</pose>
        <scale>1 1 1</scale>
        <link name='link'>
          <pose>3.41191 -16.2936 0 0 -0 1.60031</pose>
          <velocity>0 0 0 0 -0 0</velocity>
          <acceleration>0 0 0 0 -0 0</acceleration>
          <wrench>0 0 0 0 -0 0</wrench>
        </link>
      </model>
      <model name='car'>
        <pose>-0.180201 0.182365 0.020795 1.7e-05 0.005495 0.016459</pose>
        <scale>1 1 1</scale>
        <link name='back_left_wheel'>
          <pose>-0.376776 0.629187 0.167941 -1.57078 -0.973882 0.016448</pose>
          <velocity>-0.000672 0.000529 -0.059626 0.000859 -0.001704 0.000191</velocity>
          <acceleration>-0.365087 0.270156 -60.8609 2.36482 0.038926 -0.011378</acceleration>
          <wrench>-0.036509 0.027016 -6.08609 0 -0 0</wrench>
        </link>
        <link name='back_left_wheel_shock'>
          <pose>-0.376776 0.629187 0.167941 1.7e-05 0.005495 0.016459</pose>
          <velocity>-0.000671 0.000524 -0.059626 -0.000548 0.000797 0.000208</velocity>
          <acceleration>-0.375596 0.238018 -60.8611 -0.780698 -0.666898 0.321496</acceleration>
          <wrench>-0.003756 0.00238 -0.608611 0 -0 0</wrench>
        </link>
        <link name='back_right_wheel'>
          <pose>-0.361963 -0.270691 0.167941 -1.57079 -0.801001 0.016451</pose>
          <velocity>-0.000487 0.000536 -0.059297 0.000866 -0.001472 0.000248</velocity>
          <acceleration>-0.223588 0.272319 -60.5292 2.39691 0.039453 0.171511</acceleration>
          <wrench>-0.022359 0.027232 -6.05292 0 -0 0</wrench>
        </link>
        <link name='back_right_wheel_shock'>
          <pose>-0.361963 -0.270691 0.167941 1.7e-05 0.005495 0.016459</pose>
          <velocity>-0.000488 0.00053 -0.059298 -0.000553 0.000796 0.000212</velocity>
          <acceleration>-0.211607 0.24028 -60.5294 -0.728689 0.993921 -0.226593</acceleration>
          <wrench>-0.002116 0.002403 -0.605294 0 -0 0</wrench>
        </link>
        <link name='base_footprint'>
          <pose>-0.180201 0.182365 0.020795 1.7e-05 0.005495 0.016459</pose>
          <velocity>-0.000365 0.000366 0.000885 -0.000595 0.000796 0.000215</velocity>
          <acceleration>0.022563 0.00463 -0.025474 0.244749 0.173369 0.057582</acceleration>
          <wrench>0.063177 0.012965 -0.071327 0 -0 0</wrench>
        </link>
        <link name='front_left_wheel'>
          <pose>0.556012 0.644541 0.167999 -1.57067 -1.40837 0.01412</pose>
          <velocity>-0.000354 0.00022 -0.000244 0.038478 -0.002442 0.000796</velocity>
          <acceleration>-0.085732 -0.65426 -0.604126 2.93781 0.22621 -2.97305</acceleration>
          <wrench>-0.008573 -0.065426 -0.060413 0 -0 0</wrench>
        </link>
        <link name='front_left_wheel_shock'>
          <pose>0.556012 0.644541 0.167997 1.7e-05 0.005495 0.016459</pose>
          <velocity>-0.000349 9.9e-05 -0.000247 -0.0004 0.000799 0.0002</velocity>
          <acceleration>-0.100866 -0.840389 -0.604125 1.63502 -1.01344 0.432365</acceleration>
          <wrench>-0.001009 -0.008404 -0.006041 0 -0 0</wrench>
        </link>
        <link name='front_left_wheel_steer'>
          <pose>0.556012 0.644541 0.167998 3.2e-05 0.005495 0.014247</pose>
          <velocity>-0.000349 0.000224 -0.000246 0.053779 0.001569 0.000764</velocity>
          <acceleration>-0.073334 -0.640252 -0.604233 -0.917337 1.42182 -1.311</acceleration>
          <wrench>-0.007333 -0.064025 -0.060423 0 -0 0</wrench>
        </link>
        <link name='front_right_wheel'>
          <pose>0.570825 -0.255338 0.167997 -1.57087 -1.02636 0.002101</pose>
          <velocity>-0.000165 0.001486 -0.001246 -0.058128 -0.001598 -0.001473</velocity>
          <acceleration>0.145833 0.36915 0.294914 -1.0058 0.693819 0.096215</acceleration>
          <wrench>0.014583 0.036915 0.029491 0 -0 0</wrench>
        </link>
        <link name='front_right_wheel_shock'>
          <pose>0.570825 -0.255336 0.167997 1.7e-05 0.005495 0.016459</pose>
          <velocity>-0.000141 0.00034 -0.001352 -0.000563 0.000795 0.000269</velocity>
          <acceleration>0.05814 -0.130983 0.303254 1.35811 1.37404 -0.300553</acceleration>
          <wrench>0.000581 -0.00131 0.003033 0 -0 0</wrench>
        </link>
        <link name='front_right_wheel_steer'>
          <pose>0.570825 -0.255338 0.167997 -7.5e-05 0.005495 0.002038</pose>
          <velocity>-0.000162 0.001264 -0.001372 0.023404 0.000844 -0.001956</velocity>
          <acceleration>0.133592 0.327691 0.304038 -0.835041 0.248276 1.75894</acceleration>
          <wrench>0.013359 0.032769 0.030404 0 -0 0</wrench>
        </link>
      </model>
      <model name='ground_plane'>
        <pose>0 0 0 0 -0 0</pose>
        <scale>1 1 1</scale>
        <link name='link'>
          <pose>0 0 0 0 -0 0</pose>
          <velocity>0 0 0 0 -0 0</velocity>
          <acceleration>0 0 0 0 -0 0</acceleration>
          <wrench>0 0 0 0 -0 0</wrench>
        </link>
      </model>
      <model name='law_office'>
        <pose>9.03494 21.7982 0 0 -0 0</pose>
        <scale>1 1 1</scale>
        <link name='link'>
          <pose>9.03494 21.7982 0 0 -0 0</pose>
          <velocity>0 0 0 0 -0 0</velocity>
          <acceleration>0 0 0 0 -0 0</acceleration>
          <wrench>0 0 0 0 -0 0</wrench>
        </link>
      </model>
      <model name='pine_tree'>
        <pose>19.4895 12.7233 0 0 -0 0</pose>
        <scale>1 1 1</scale>
        <link name='link'>
          <pose>19.4895 12.7233 0 0 -0 0</pose>
          <velocity>0 0 0 0 -0 0</velocity>
          <acceleration>0 0 0 0 -0 0</acceleration>
          <wrench>0 0 0 0 -0 0</wrench>
        </link>
      </model>
      <model name='pine_tree_0'>
        <pose>14.5466 13.5254 0 0 -0 0</pose>
        <scale>1 1 1</scale>
        <link name='link'>
          <pose>14.5466 13.5254 0 0 -0 0</pose>
          <velocity>0 0 0 0 -0 0</velocity>
          <acceleration>0 0 0 0 -0 0</acceleration>
          <wrench>0 0 0 0 -0 0</wrench>
        </link>
      </model>
      <light name='sun'>
        <pose>0 0 10 0 -0 0</pose>
      </light>
    </state>
    <gui fullscreen='0'>
      <camera name='user_camera'>
        <pose>17.4035 -69.0253 20.0366 0 0.207643 1.5802</pose>
        <view_controller>orbit</view_controller>
        <projection_type>perspective</projection_type>
      </camera>
    </gui>
  </world>
</sdf>